Workbook

Sheet README
A1: Northfield Returns Integrity: sample golden dataset
A2: SYNTHETIC DATA. Every row is invented to show the structure. No real customer data. All amounts are in Indian rupees (₹).
A4: What this is
A5: A golden dataset is the answer key for the returns-abuse model: past returns with a verified label (abuse type or honest).
A6: It is used to train the model, to measure accuracy before launch, and to test fairness. The real version is built in Phase 0.
A8: Tabs
A9: Golden Dataset: one row per past return, with facts from the source systems and the verified label.
A10: Data Dictionary: what each column means and which system it comes from.
A11: Summary: counts and shares by label and by label source. Calculated with formulas, so it updates if rows change.
A12: Backtest: the MVP scoring rules written as formulas, run against every row. Shows accuracy, abusers caught and loss prevented, and lets you change the threshold.
A14: How to read a row
A15: Columns A–H are facts joined from orders, payments, carrier tracking and account data.
... A23: Columns: the real table has many more features (warehouse grading, chat claim counts, linked cards and devices).

Sheet Golden Dataset
A1: return_id | B1: customer_id | C1: date | D1: item_value | E1: refunds_no_scan_60d | F1: linked_abusive_accounts | G1: account_age_days | H1: carrier_scanned | I1: analyst_label | J1: label_source
A2: R-10482 | B2: C-7731 | C2: 46313 | D2: 129 | E2: 3 | F2: 2 | G2: 21 | H2: No | I2: Abuse: refund without return | J2: Confirmed by 2 analysts
A3: R-10483 | B3: C-0912 | C3: 46313 | D3: 72 | E3: 0 | F3: 0 | G3: 1520 | H3: Yes | I3: Honest | J3: Item received and graded
A4: R-10484 | B4: C-5521 | C4: 46314 | D4: 58 | E4: 1 | F4: 0 | G4: 540 | H4: No | I4: Honest: carrier lost parcel | J4: Overturned on appeal
A5: R-08025 | B5: C-2198 | C5: 45597 | D5: 72 | E5: 0 | F5: 0 | G5: 392 | H5: Yes | I5: Honest | J5: Item received and graded
A6: R-08039 | B6: C-1171 | C6: 45598 | D6: 95 | E6: 0 | F6: 0 | G6: 580 | H6: Yes | I6: Honest | J6: Random audit, cleared
A7: R-08072 | B7: C-2281 | C7: 45599 | D7: 58 | E7: 2 | F7: 0 | G7: 311 | H7: No | I7: Abuse: refund without return | J7: Confirmed by 2 analysts
A8: R-08120 | B8: C-8778 | C8: 45601 | D8: 52 | E8: 0 | F8: 0 | G8: 28 | H8: Yes | I8: Honest | J8: Item received and graded
A9: R-08126 | B9: C-2733 | C9: 45603 | D9: 129 | E9: 4 | F9: 0 | G9: 26 | H9: No | I9: Abuse: refund without return | J9: Confirmed by 2 analysts
A10: R-08145 | B10: C-6960 | C10: 45615 | D10: 129 | E10: 2 | F10: 0 | G10: 1986 | H10: No | I10: Abuse: refund without return | J10: Confirmed by 2 analysts
A11: R-08045 | B11: C-4180 | C11: 45619 | D11: 85 | E11: 0 | F11: 0 | G11: 1707 | H11: Yes | I11: Honest | J11: Item received and graded
A12: R-08176 | B12: C-1057 | C12: 45620 | D12: 110 | E12: 0 | F12: 0 | G12: 576 | H12: Yes | I12: Honest | J12: Item received and graded
A13: R-08069 | B13: C-6108 | C13: 45629 | D13: 134 | E13: 1 | F13: 0 | G13: 120 | H13: Yes | I13: Honest | J13: Item received and graded
... A201: R-08050 | B201: C-6538 | C201: 46309 | D201: 148 | E201: 0 | F201: 0 | G201: 662 | H201: Yes | I201: Abuse: wear and return | J201: Warehouse graded as worn
A203: Rows 2–4 (blue) are the worked examples from the presentation. All data is synthetic.

Sheet Summary
A1: Summary of the sample golden dataset
A2: All figures are formulas over the Golden Dataset tab.
A4: Label | B4: Returns | C4: Share of rows | D4: Average item value (₹)
A5: Honest | B5: =COUNTIF('Golden Dataset'!$I$2:$I$201,A5) -> 119 | C5: =B5/$B$11 -> 0.595 | D5: =IFERROR(AVERAGEIF('Golden Dataset'!$I$2:$I$201,A5,'Golden Dataset'!$D$2:$D$201),0) -> 66.529412
A6: Honest: carrier lost parcel | B6: =COUNTIF('Golden Dataset'!$I$2:$I$201,A6) -> 13 | C6: =B6/$B$11 -> 0.065 | D6: =IFERROR(AVERAGEIF('Golden Dataset'!$I$2:$I$201,A6,'Golden Dataset'!$D$2:$D$201),0) -> 65.538462
A7: Abuse: refund without return | B7: =COUNTIF('Golden Dataset'!$I$2:$I$201,A7) -> 29 | C7: =B7/$B$11 -> 0.145 | D7: =IFERROR(AVERAGEIF('Golden Dataset'!$I$2:$I$201,A7,'Golden Dataset'!$D$2:$D$201),0) -> 85.62069
A8: Abuse: wear and return | B8: =COUNTIF('Golden Dataset'!$I$2:$I$201,A8) -> 16 | C8: =B8/$B$11 -> 0.08 | D8: =IFERROR(AVERAGEIF('Golden Dataset'!$I$2:$I$201,A8,'Golden Dataset'!$D$2:$D$201),0) -> 149.1875
A9: Abuse: repeated damage claims | B9: =COUNTIF('Golden Dataset'!$I$2:$I$201,A9) -> 14 | C9: =B9/$B$11 -> 0.07 | D9: =IFERROR(AVERAGEIF('Golden Dataset'!$I$2:$I$201,A9,'Golden Dataset'!$D$2:$D$201),0) -> 81
A10: Abuse: reseller ring | B10: =COUNTIF('Golden Dataset'!$I$2:$I$201,A10) -> 9 | C10: =B10/$B$11 -> 0.045 | D10: =IFERROR(AVERAGEIF('Golden Dataset'!$I$2:$I$201,A10,'Golden Dataset'!$D$2:$D$201),0) -> 252.44444
A11: Total | B11: =SUM(B5:B10) -> 200 | C11: =SUM(C5:C10) -> 1 | D11: =AVERAGE('Golden Dataset'!$D$2:$D$201) -> 85.225
A12: All abuse types | B12: =COUNTIF('Golden Dataset'!$I$2:$I$201,"Abuse*") -> 68 | C12: =B12/$B$11 -> 0.34 | D12: =IFERROR(AVERAGEIF('Golden Dataset'!$I$2:$I$201,"Abuse*",'Golden Dataset'!$D$2:$D$201),0) -> 121.70588
A14: Label source | B14: Returns | C14: Share of rows
A15: Account closed after review | B15: =COUNTIF('Golden Dataset'!$J$2:$J$201,A15) -> 6 | C15: =B15/$B$11 -> 0.03
A16: Carrier confirmed loss | B16: =COUNTIF('Golden Dataset'!$J$2:$J$201,A16) -> 5 | C16: =B16/$B$11 -> 0.025
A17: Chat claim history reviewed | B17: =COUNTIF('Golden Dataset'!$J$2:$J$201,A17) -> 14 | C17: =B17/$B$11 -> 0.07
A18: Confirmed by 2 analysts | B18: =COUNTIF('Golden Dataset'!$J$2:$J$201,A18) -> 23 | C18: =B18/$B$11 -> 0.115
A19: Item received and graded | B19: =COUNTIF('Golden Dataset'!$J$2:$J$201,A19) -> 95 | C19: =B19/$B$11 -> 0.475
A20: Linked to confirmed ring | B20: =COUNTIF('Golden Dataset'!$J$2:$J$201,A20) -> 9 | C20: =B20/$B$11 -> 0.045
A21: Overturned on appeal | B21: =COUNTIF('Golden Dataset'!$J$2:$J$201,A21) -> 8 | C21: =B21/$B$11 -> 0.04
A22: Random audit, cleared | B22: =COUNTIF('Golden Dataset'!$J$2:$J$201,A22) -> 24 | C22: =B22/$B$11 -> 0.12
A23: Warehouse graded as worn | B23: =COUNTIF('Golden Dataset'!$J$2:$J$201,A23) -> 16 | C23: =B23/$B$11 -> 0.08
A25: Note: abuse is over-sampled to about a third of rows so each abuse type has enough examples. In real traffic abuse is about 10% of returns (Section 1 assumption).

Sheet Data Dictionary
A1: Column | B1: Meaning | C1: Source system | D1: Type | E1: Example
A2: return_id | B2: Unique ID of the return | C2: Order management | D2: Text | E2: R-10482
A3: customer_id | B3: Pseudonymised customer ID (real IDs never used in training) | C3: Customer matching | D3: Text | E3: C-7731
A4: date | B4: Date the return was started | C4: Order management | D4: Date | E4: 2026-10-18
A5: item_value | B5: Refund value of the returned item, in Indian rupees (₹) | C5: Payments | D5: Number (₹) | E5: 3499
A6: refunds_no_scan_60d | B6: Refunds in the previous 60 days where the carrier never scanned the parcel | C6: Payments + carrier tracking | D6: Count | E6: 3
A7: linked_abusive_accounts | B7: Accounts sharing an address or card with this one that were confirmed as abusive | C7: Account links | D7: Count | E7: 2
A8: account_age_days | B8: Days since the account was created | C8: Customer accounts | D8: Count | E8: 21
A9: carrier_scanned | B9: Whether the carrier has scanned this return parcel | C9: Carrier tracking | D9: Yes / No | E9: No
A10: analyst_label | B10: The verified answer: Honest, or the abuse type | C10: Trust & safety review | D10: Category | E10: Abuse: refund without return
A11: label_source | B11: How the label was verified | C11: Trust & safety review | D11: Category | E11: Confirmed by 2 analysts
A13: Not included on purpose: name, gender, age, postcode, chat language, device type, payment method type. The model judges behaviour, never identity.

Sheet Backtest
A1: Backtest: MVP scoring rules run against the golden dataset
A2: Blue cells on yellow are inputs you can change. Everything else is a formula.
A4: return_id | B4: analyst_label | C4: risk_score | D4: lane | E4: held | F4: is_abuse | G4: is_rwr | H4: outcome | L4: Inputs
A5: ='Golden Dataset'!A2 -> R-10482 | B5: ='Golden Dataset'!I2 -> Abuse: refund without return | C5: =MIN(99,$M$5*'Golden Dataset'!E2+$M$6*'Golden Dataset'!F2+IF('Golden Dataset'!G2<30,$M$7,0)+IF('Golden Dataset'!H2="No",$M$8,0)) -> 99 | D5: =IF(C5>=$M$9,"Hold and review",IF(C5>=$M$10,"Refund on carrier scan","Approve")) -> Hold and review | E5: =IF(C5>=$M$9,1,0) -> 1 | F5: =IF(LEFT(B5,5)="Abuse",1,0) -> 1 | G5: =IF(B5="Abuse: refund without return",1,0) -> 1 | H5: =IF(E5=1,IF(F5=1,"Correct hold","False alarm"),IF(F5=1,"Missed","Correctly left alone")) -> Correct hold | L5: Points per earlier refund with no carrier scan | M5: 22
A6: ='Golden Dataset'!A3 -> R-10483 | B6: ='Golden Dataset'!I3 -> Honest | C6: =MIN(99,$M$5*'Golden Dataset'!E3+$M$6*'Golden Dataset'!F3+IF('Golden Dataset'!G3<30,$M$7,0)+IF('Golden Dataset'!H3="No",$M$8,0)) -> 0 | D6: =IF(C6>=$M$9,"Hold and review",IF(C6>=$M$10,"Refund on carrier scan","Approve")) -> Approve | E6: =IF(C6>=$M$9,1,0) -> 0 | F6: =IF(LEFT(B6,5)="Abuse",1,0) -> 0 | G6: =IF(B6="Abuse: refund without return",1,0) -> 0 | H6: =IF(E6=1,IF(F6=1,"Correct hold","False alarm"),IF(F6=1,"Missed","Correctly left alone")) -> Correctly left alone | L6: Points per linked abusive account | M6: 20
A7: ='Golden Dataset'!A4 -> R-10484 | B7: ='Golden Dataset'!I4 -> Honest: carrier lost parcel | C7: =MIN(99,$M$5*'Golden Dataset'!E4+$M$6*'Golden Dataset'!F4+IF('Golden Dataset'!G4<30,$M$7,0)+IF('Golden Dataset'!H4="No",$M$8,0)) -> 30 | D7: =IF(C7>=$M$9,"Hold and review",IF(C7>=$M$10,"Refund on carrier scan","Approve")) -> Refund on carrier scan | E7: =IF(C7>=$M$9,1,0) -> 0 | F7: =IF(LEFT(B7,5)="Abuse",1,0) -> 0 | G7: =IF(B7="Abuse: refund without return",1,0) -> 0 | H7: =IF(E7=1,IF(F7=1,"Correct hold","False alarm"),IF(F7=1,"Missed","Correctly left alone")) -> Correctly left alone | L7: Points if account is under 30 days old | M7: 12
A8: ='Golden Dataset'!A5 -> R-08025 | B8: ='Golden Dataset'!I5 -> Honest | C8: =MIN(99,$M$5*'Golden Dataset'!E5+$M$6*'Golden Dataset'!F5+IF('Golden Dataset'!G5<30,$M$7,0)+IF('Golden Dataset'!H5="No",$M$8,0)) -> 0 | D8: =IF(C8>=$M$9,"Hold and review",IF(C8>=$M$10,"Refund on carrier scan","Approve")) -> Approve | E8: =IF(C8>=$M$9,1,0) -> 0 | F8: =IF(LEFT(B8,5)="Abuse",1,0) -> 0 | G8: =IF(B8="Abuse: refund without return",1,0) -> 0 | H8: =IF(E8=1,IF(F8=1,"Correct hold","False alarm"),IF(F8=1,"Missed","Correctly left alone")) -> Correctly left alone | L8: Points if this parcel has no carrier scan | M8: 8
A9: ='Golden Dataset'!A6 -> R-08039 | B9: ='Golden Dataset'!I6 -> Honest | C9: =MIN(99,$M$5*'Golden Dataset'!E6+$M$6*'Golden Dataset'!F6+IF('Golden Dataset'!G6<30,$M$7,0)+IF('Golden Dataset'!H6="No",$M$8,0)) -> 0 | D9: =IF(C9>=$M$9,"Hold and review",IF(C9>=$M$10,"Refund on carrier scan","Approve")) -> Approve | E9: =IF(C9>=$M$9,1,0) -> 0 | F9: =IF(LEFT(B9,5)="Abuse",1,0) -> 0 | G9: =IF(B9="Abuse: refund without return",1,0) -> 0 | H9: =IF(E9=1,IF(F9=1,"Correct hold","False alarm"),IF(F9=1,"Missed","Correctly left alone")) -> Correctly left alone | L9: Hold-and-review threshold (score) | M9: 60
A10: ='Golden Dataset'!A7 -> R-08072 | B10: ='Golden Dataset'!I7 -> Abuse: refund without return | C10: =MIN(99,$M$5*'Golden Dataset'!E7+$M$6*'Golden Dataset'!F7+IF('Golden Dataset'!G7<30,$M$7,0)+IF('Golden Dataset'!H7="No",$M$8,0)) -> 52 | D10: =IF(C10>=$M$9,"Hold and review",IF(C10>=$M$10,"Refund on carrier scan","Approve")) -> Refund on carrier scan | E10: =IF(C10>=$M$9,1,0) -> 0 | F10: =IF(LEFT(B10,5)="Abuse",1,0) -> 1 | G10: =IF(B10="Abuse: refund without return",1,0) -> 1 | H10: =IF(E10=1,IF(F10=1,"Correct hold","False alarm"),IF(F10=1,"Missed","Correctly left alone")) -> Missed | L10: Refund-on-scan threshold (score) | M10: 30
A11: ='Golden Dataset'!A8 -> R-08120 | B11: ='Golden Dataset'!I8 -> Honest | C11: =MIN(99,$M$5*'Golden Dataset'!E8+$M$6*'Golden Dataset'!F8+IF('Golden Dataset'!G8<30,$M$7,0)+IF('Golden Dataset'!H8="No",$M$8,0)) -> 12 | D11: =IF(C11>=$M$9,"Hold and review",IF(C11>=$M$10,"Refund on carrier scan","Approve")) -> Approve | E11: =IF(C11>=$M$9,1,0) -> 0 | F11: =IF(LEFT(B11,5)="Abuse",1,0) -> 0 | G11: =IF(B11="Abuse: refund without return",1,0) -> 0 | H11: =IF(E11=1,IF(F11=1,"Correct hold","False alarm"),IF(F11=1,"Missed","Correctly left alone")) -> Correctly left alone | L11: Yearly refund-without-return loss ($M) | M11: 33
A12: ='Golden Dataset'!A9 -> R-08126 | B12: ='Golden Dataset'!I9 -> Abuse: refund without return | C12: =MIN(99,$M$5*'Golden Dataset'!E9+$M$6*'Golden Dataset'!F9+IF('Golden Dataset'!G9<30,$M$7,0)+IF('Golden Dataset'!H9="No",$M$8,0)) -> 99 | D12: =IF(C12>=$M$9,"Hold and review",IF(C12>=$M$10,"Refund on carrier scan","Approve")) -> Hold and review | E12: =IF(C12>=$M$9,1,0) -> 1 | F12: =IF(LEFT(B12,5)="Abuse",1,0) -> 1 | G12: =IF(B12="Abuse: refund without return",1,0) -> 1 | H12: =IF(E12=1,IF(F12=1,"Correct hold","False alarm"),IF(F12=1,"Missed","Correctly left alone")) -> Correct hold | L12: Loss stopped per caught abuser | M12: 0.62
A13: ='Golden Dataset'!A10 -> R-08145 | B13: ='Golden Dataset'!I10 -> Abuse: refund without return | C13: =MIN(99,$M$5*'Golden Dataset'!E10+$M$6*'Golden Dataset'!F10+IF('Golden Dataset'!G10<30,$M$7,0)+IF('Golden Dataset'!H10="No",$M$8,0)) -> 52 | D13: =IF(C13>=$M$9,"Hold and review",IF(C13>=$M$10,"Refund on carrier scan","Approve")) -> Refund on carrier scan | E13: =IF(C13>=$M$9,1,0) -> 0 | F13: =IF(LEFT(B13,5)="Abuse",1,0) -> 1 | G13: =IF(B13="Abuse: refund without return",1,0) -> 1 | H13: =IF(E13=1,IF(F13=1,"Correct hold","False alarm"),IF(F13=1,"Missed","Correctly left alone")) -> Missed | L13: Accuracy guardrail (precision) | M13: 0.9
A14: ='Golden Dataset'!A11 -> R-08045 | B14: ='Golden Dataset'!I11 -> Honest | C14: =MIN(99,$M$5*'Golden Dataset'!E11+$M$6*'Golden Dataset'!F11+IF('Golden Dataset'!G11<30,$M$7,0)+IF('Golden Dataset'!H11="No",$M$8,0)) -> 0 | D14: =IF(C14>=$M$9,"Hold and review",IF(C14>=$M$10,"Refund on carrier scan","Approve")) -> Approve | E14: =IF(C14>=$M$9,1,0) -> 0 | F14: =IF(LEFT(B14,5)="Abuse",1,0) -> 0 | G14: =IF(B14="Abuse: refund without return",1,0) -> 0 | H14: =IF(E14=1,IF(F14=1,"Correct hold","False alarm"),IF(F14=1,"Missed","Correctly left alone")) -> Correctly left alone | L14: Sources: score weights and thresholds are the MVP rules from the prototype. $33M and 62% come from the Section 1 cost model (assumptions). 90% is the launch guardrail.
A15: ='Golden Dataset'!A12 -> R-08176 | B15: ='Golden Dataset'!I12 -> Honest | C15: =MIN(99,$M$5*'Golden Dataset'!E12+$M$6*'Golden Dataset'!F12+IF('Golden Dataset'!G12<30,$M$7,0)+IF('Golden Dataset'!H12="No",$M$8,0)) -> 0 | D15: =IF(C15>=$M$9,"Hold and review",IF(C15>=$M$10,"Refund on carrier scan","Approve")) -> Approve | E15: =IF(C15>=$M$9,1,0) -> 0 | F15: =IF(LEFT(B15,5)="Abuse",1,0) -> 0 | G15: =IF(B15="Abuse: refund without return",1,0) -> 0 | H15: =IF(E15=1,IF(F15=1,"Correct hold","False alarm"),IF(F15=1,"Missed","Correctly left alone")) -> Correctly left alone
A16: ='Golden Dataset'!A13 -> R-08069 | B16: ='Golden Dataset'!I13 -> Honest | C16: =MIN(99,$M$5*'Golden Dataset'!E13+$M$6*'Golden Dataset'!F13+IF('Golden Dataset'!G13<30,$M$7,0)+IF('Golden Dataset'!H13="No",$M$8,0)) -> 22 | D16: =IF(C16>=$M$9,"Hold and review",IF(C16>=$M$10,"Refund on carrier scan","Approve")) -> Approve | E16: =IF(C16>=$M$9,1,0) -> 0 | F16: =IF(LEFT(B16,5)="Abuse",1,0) -> 0 | G16: =IF(B16="Abuse: refund without return",1,0) -> 0 | H16: =IF(E16=1,IF(F16=1,"Correct hold","False alarm"),IF(F16=1,"Missed","Correctly left alone")) -> Correctly left alone
A17: ='Golden Dataset'!A14 -> R-08082 | B17: ='Golden Dataset'!I14 -> Honest | C17: =MIN(99,$M$5*'Golden Dataset'!E14+$M$6*'Golden Dataset'!F14+IF('Golden Dataset'!G14<30,$M$7,0)+IF('Golden Dataset'!H14="No",$M$8,0)) -> 22 | D17: =IF(C17>=$M$9,"Hold and review",IF(C17>=$M$10,"Refund on carrier scan","Approve")) -> Approve | E17: =IF(C17>=$M$9,1,0) -> 0 | F17: =IF(LEFT(B17,5)="Abuse",1,0) -> 0 | G17: =IF(B17="Abuse: refund without return",1,0) -> 0 | H17: =IF(E17=1,IF(F17=1,"Correct hold","False alarm"),IF(F17=1,"Missed","Correctly left alone")) -> Correctly left alone | L17: Results at the hold threshold
A18: ='Golden Dataset'!A15 -> R-08128 | B18: ='Golden Dataset'!I15 -> Honest | C18: =MIN(99,$M$5*'Golden Dataset'!E15+$M$6*'Golden Dataset'!F15+IF('Golden Dataset'!G15<30,$M$7,0)+IF('Golden Dataset'!H15="No",$M$8,0)) -> 30 | D18: =IF(C18>=$M$9,"Hold and review",IF(C18>=$M$10,"Refund on carrier scan","Approve")) -> Refund on carrier scan | E18: =IF(C18>=$M$9,1,0) -> 0 | F18: =IF(LEFT(B18,5)="Abuse",1,0) -> 0 | G18: =IF(B18="Abuse: refund without return",1,0) -> 0 | H18: =IF(E18=1,IF(F18=1,"Correct hold","False alarm"),IF(F18=1,"Missed","Correctly left alone")) -> Correctly left alone | L18: Returns held for review | M18: =SUM($E$5:$E$204) -> 30
A19: ='Golden Dataset'!A16 -> R-08031 | B19: ='Golden Dataset'!I16 -> Honest | C19: =MIN(99,$M$5*'Golden Dataset'!E16+$M$6*'Golden Dataset'!F16+IF('Golden Dataset'!G16<30,$M$7,0)+IF('Golden Dataset'!H16="No",$M$8,0)) -> 0 | D19: =IF(C19>=$M$9,"Hold and review",IF(C19>=$M$10,"Refund on carrier scan","Approve")) -> Approve | E19: =IF(C19>=$M$9,1,0) -> 0 | F19: =IF(LEFT(B19,5)="Abuse",1,0) -> 0 | G19: =IF(B19="Abuse: refund without return",1,0) -> 0 | H19: =IF(E19=1,IF(F19=1,"Correct hold","False alarm"),IF(F19=1,"Missed","Correctly left alone")) -> Correctly left alone | L19: Of which really abusive | M19: =SUMPRODUCT($E$5:$E$204,$F$5:$F$204) -> 29
A20: ='Golden Dataset'!A17 -> R-08169 | B20: ='Golden Dataset'!I17 -> Honest | C20: =MIN(99,$M$5*'Golden Dataset'!E17+$M$6*'Golden Dataset'!F17+IF('Golden Dataset'!G17<30,$M$7,0)+IF('Golden Dataset'!H17="No",$M$8,0)) -> 0 | D20: =IF(C20>=$M$9,"Hold and review",IF(C20>=$M$10,"Refund on carrier scan","Approve")) -> Approve | E20: =IF(C20>=$M$9,1,0) -> 0 | F20: =IF(LEFT(B20,5)="Abuse",1,0) -> 0 | G20: =IF(B20="Abuse: refund without return",1,0) -> 0 | H20: =IF(E20=1,IF(F20=1,"Correct hold","False alarm"),IF(F20=1,"Missed","Correctly left alone")) -> Correctly left alone | L20: False alarms (honest customers held) | M20: =COUNTIF($H$5:$H$204,"False alarm") -> 1
A21: ='Golden Dataset'!A18 -> R-08143 | B21: ='Golden Dataset'!I18 -> Abuse: repeated damage claims | C21: =MIN(99,$M$5*'Golden Dataset'!E18+$M$6*'Golden Dataset'!F18+IF('Golden Dataset'!G18<30,$M$7,0)+IF('Golden Dataset'!H18="No",$M$8,0)) -> 8 | D21: =IF(C21>=$M$9,"Hold and review",IF(C21>=$M$10,"Refund on carrier scan","Approve")) -> Approve | E21: =IF(C21>=$M$9,1,0) -> 0 | F21: =IF(LEFT(B21,5)="Abuse",1,0) -> 1 | G21: =IF(B21="Abuse: refund without return",1,0) -> 0 | H21: =IF(E21=1,IF(F21=1,"Correct hold","False alarm"),IF(F21=1,"Missed","Correctly left alone")) -> Missed | L21: Accuracy of holds (precision) | M21: =IFERROR(M19/M18,0) -> 0.96666667
A22: ='Golden Dataset'!A19 -> R-08063 | B22: ='Golden Dataset'!I19 -> Abuse: wear and return | C22: =MIN(99,$M$5*'Golden Dataset'!E19+$M$6*'Golden Dataset'!F19+IF('Golden Dataset'!G19<30,$M$7,0)+IF('Golden Dataset'!H19="No",$M$8,0)) -> 0 | D22: =IF(C22>=$M$9,"Hold and review",IF(C22>=$M$10,"Refund on carrier scan","Approve")) -> Approve | E22: =IF(C22>=$M$9,1,0) -> 0 | F22: =IF(LEFT(B22,5)="Abuse",1,0) -> 1 | G22: =IF(B22="Abuse: refund without return",1,0) -> 0 | H22: =IF(E22=1,IF(F22=1,"Correct hold","False alarm"),IF(F22=1,"Missed","Correctly left alone")) -> Missed | L22: Refund-without-return abusers caught (recall) | M22: =IFERROR(SUMPRODUCT($E$5:$E$204,$G$5:$G$204)/SUM($G$5:$G$204),0) -> 0.68965517
A23: ='Golden Dataset'!A20 -> R-08061 | B23: ='Golden Dataset'!I20 -> Honest | C23: =MIN(99,$M$5*'Golden Dataset'!E20+$M$6*'Golden Dataset'!F20+IF('Golden Dataset'!G20<30,$M$7,0)+IF('Golden Dataset'!H20="No",$M$8,0)) -> 0 | D23: =IF(C23>=$M$9,"Hold and review",IF(C23>=$M$10,"Refund on carrier scan","Approve")) -> Approve | E23: =IF(C23>=$M$9,1,0) -> 0 | F23: =IF(LEFT(B23,5)="Abuse",1,0) -> 0 | G23: =IF(B23="Abuse: refund without return",1,0) -> 0 | H23: =IF(E23=1,IF(F23=1,"Correct hold","False alarm"),IF(F23=1,"Missed","Correctly left alone")) -> Correctly left alone | L23: Loss prevented per year ($M) | M23: =$M$11*$M$12*M22 -> 14.110345
A24: ='Golden Dataset'!A21 -> R-08060 | B24: ='Golden Dataset'!I21 -> Honest | C24: =MIN(99,$M$5*'Golden Dataset'!E21+$M$6*'Golden Dataset'!F21+IF('Golden Dataset'!G21<30,$M$7,0)+IF('Golden Dataset'!H21="No",$M$8,0)) -> 0 | D24: =IF(C24>=$M$9,"Hold and review",IF(C24>=$M$10,"Refund on carrier scan","Approve")) -> Approve | E24: =IF(C24>=$M$9,1,0) -> 0 | F24: =IF(LEFT(B24,5)="Abuse",1,0) -> 0 | G24: =IF(B24="Abuse: refund without return",1,0) -> 0 | H24: =IF(E24=1,IF(F24=1,"Correct hold","False alarm"),IF(F24=1,"Missed","Correctly left alone")) -> Correctly left alone | L24: Meets accuracy guardrail? | M24: =IF(M21>=$M$13,"Yes","No") -> Yes
A25: ='Golden Dataset'!A22 -> R-08083 | B25: ='Golden Dataset'!I22 -> Honest | C25: =MIN(99,$M$5*'Golden Dataset'!E22+$M$6*'Golden Dataset'!F22+IF('Golden Dataset'!G22<30,$M$7,0)+IF('Golden Dataset'!H22="No",$M$8,0)) -> 0 | D25: =IF(C25>=$M$9,"Hold and review",IF(C25>=$M$10,"Refund on carrier scan","Approve")) -> Approve | E25: =IF(C25>=$M$9,1,0) -> 0 | F25: =IF(LEFT(B25,5)="Abuse",1,0) -> 0 | G25: =IF(B25="Abuse: refund without return",1,0) -> 0 | H25: =IF(E25=1,IF(F25=1,"Correct hold","False alarm"),IF(F25=1,"Missed","Correctly left alone")) -> Correctly left alone
A26: ='Golden Dataset'!A23 -> R-08084 | B26: ='Golden Dataset'!I23 -> Honest | C26: =MIN(99,$M$5*'Golden Dataset'!E23+$M$6*'Golden Dataset'!F23+IF('Golden Dataset'!G23<30,$M$7,0)+IF('Golden Dataset'!H23="No",$M$8,0)) -> 22 | D26: =IF(C26>=$M$9,"Hold and review",IF(C26>=$M$10,"Refund on carrier scan","Approve")) -> Approve | E26: =IF(C26>=$M$9,1,0) -> 0 | F26: =IF(LEFT(B26,5)="Abuse",1,0) -> 0 | G26: =IF(B26="Abuse: refund without return",1,0) -> 0 | H26: =IF(E26=1,IF(F26=1,"Correct hold","False alarm"),IF(F26=1,"Missed","Correctly left alone")) -> Correctly left alone
A27: ='Golden Dataset'!A24 -> R-08180 | B27: ='Golden Dataset'!I24 -> Honest | C27: =MIN(99,$M$5*'Golden Dataset'!E24+$M$6*'Golden Dataset'!F24+IF('Golden Dataset'!G24<30,$M$7,0)+IF('Golden Dataset'!H24="No",$M$8,0)) -> 0 | D27: =IF(C27>=$M$9,"Hold and review",IF(C27>=$M$10,"Refund on carrier scan","Approve")) -> Approve | E27: =IF(C27>=$M$9,1,0) -> 0 | F27: =IF(LEFT(B27,5)="Abuse",1,0) -> 0 | G27: =IF(B27="Abuse: refund without return",1,0) -> 0 | H27: =IF(E27=1,IF(F27=1,"Correct hold","False alarm"),IF(F27=1,"Missed","Correctly left alone")) -> Correctly left alone | L27: Trade-off by threshold
A28: ='Golden Dataset'!A25 -> R-08103 | B28: ='Golden Dataset'!I25 -> Honest | C28: =MIN(99,$M$5*'Golden Dataset'!E25+$M$6*'Golden Dataset'!F25+IF('Golden Dataset'!G25<30,$M$7,0)+IF('Golden Dataset'!H25="No",$M$8,0)) -> 0 | D28: =IF(C28>=$M$9,"Hold and review",IF(C28>=$M$10,"Refund on carrier scan","Approve")) -> Approve | E28: =IF(C28>=$M$9,1,0) -> 0 | F28: =IF(LEFT(B28,5)="Abuse",1,0) -> 0 | G28: =IF(B28="Abuse: refund without return",1,0) -> 0 | H28: =IF(E28=1,IF(F28=1,"Correct hold","False alarm"),IF(F28=1,"Missed","Correctly left alone")) -> Correctly left alone | L28: Threshold | M28: Held | N28: Really abusive | O28: Precision | P28: RWR caught | Q28: Recall | R28: Loss prevented ($M) | S28: Guardrail
A29: ='Golden Dataset'!A26 -> R-08066 | B29: ='Golden Dataset'!I26 -> Honest | C29: =MIN(99,$M$5*'Golden Dataset'!E26+$M$6*'Golden Dataset'!F26+IF('Golden Dataset'!G26<30,$M$7,0)+IF('Golden Dataset'!H26="No",$M$8,0)) -> 0 | D29: =IF(C29>=$M$9,"Hold and review",IF(C29>=$M$10,"Refund on carrier scan","Approve")) -> Approve | E29: =IF(C29>=$M$9,1,0) -> 0 | F29: =IF(LEFT(B29,5)="Abuse",1,0) -> 0 | G29: =IF(B29="Abuse: refund without return",1,0) -> 0 | H29: =IF(E29=1,IF(F29=1,"Correct hold","False alarm"),IF(F29=1,"Missed","Correctly left alone")) -> Correctly left alone | L29: 30 | M29: =COUNTIF($C$5:$C$204,">="&L29) -> 59 | N29: =COUNTIFS($C$5:$C$204,">="&L29,$F$5:$F$204,1) -> 43 | O29: =IFERROR(N29/M29,0) -> 0.72881356 | P29: =COUNTIFS($C$5:$C$204,">="&L29,$G$5:$G$204,1) -> 29 | Q29: =IFERROR(P29/SUM($G$5:$G$204),0) -> 1 | R29: =$M$11*$M$12*Q29 -> 20.46 | S29: =IF(O29>=$M$13,"Pass","Fail") -> Fail
A30: ='Golden Dataset'!A27 -> R-08073 | B30: ='Golden Dataset'!I27 -> Abuse: refund without return | C30: =MIN(99,$M$5*'Golden Dataset'!E27+$M$6*'Golden Dataset'!F27+IF('Golden Dataset'!G27<30,$M$7,0)+IF('Golden Dataset'!H27="No",$M$8,0)) -> 86 | D30: =IF(C30>=$M$9,"Hold and review",IF(C30>=$M$10,"Refund on carrier scan","Approve")) -> Hold and review | E30: =IF(C30>=$M$9,1,0) -> 1 | F30: =IF(LEFT(B30,5)="Abuse",1,0) -> 1 | G30: =IF(B30="Abuse: refund without return",1,0) -> 1 | H30: =IF(E30=1,IF(F30=1,"Correct hold","False alarm"),IF(F30=1,"Missed","Correctly left alone")) -> Correct hold | L30: 40 | M30: =COUNTIF($C$5:$C$204,">="&L30) -> 43 | N30: =COUNTIFS($C$5:$C$204,">="&L30,$F$5:$F$204,1) -> 35 | O30: =IFERROR(N30/M30,0) -> 0.81395349 | P30: =COUNTIFS($C$5:$C$204,">="&L30,$G$5:$G$204,1) -> 26 | Q30: =IFERROR(P30/SUM($G$5:$G$204),0) -> 0.89655172 | R30: =$M$11*$M$12*Q30 -> 18.343448 | S30: =IF(O30>=$M$13,"Pass","Fail") -> Fail
A31: ='Golden Dataset'!A28 -> R-08104 | B31: ='Golden Dataset'!I28 -> Abuse: wear and return | C31: =MIN(99,$M$5*'Golden Dataset'!E28+$M$6*'Golden Dataset'!F28+IF('Golden Dataset'!G28<30,$M$7,0)+IF('Golden Dataset'!H28="No",$M$8,0)) -> 0 | D31: =IF(C31>=$M$9,"Hold and review",IF(C31>=$M$10,"Refund on carrier scan","Approve")) -> Approve | E31: =IF(C31>=$M$9,1,0) -> 0 | F31: =IF(LEFT(B31,5)="Abuse",1,0) -> 1 | G31: =IF(B31="Abuse: refund without return",1,0) -> 0 | H31: =IF(E31=1,IF(F31=1,"Correct hold","False alarm"),IF(F31=1,"Missed","Correctly left alone")) -> Missed | L31: 50 | M31: =COUNTIF($C$5:$C$204,">="&L31) -> 39 | N31: =COUNTIFS($C$5:$C$204,">="&L31,$F$5:$F$204,1) -> 33 | O31: =IFERROR(N31/M31,0) -> 0.84615385 | P31: =COUNTIFS($C$5:$C$204,">="&L31,$G$5:$G$204,1) -> 24 | Q31: =IFERROR(P31/SUM($G$5:$G$204),0) -> 0.82758621 | R31: =$M$11*$M$12*Q31 -> 16.932414 | S31: =IF(O31>=$M$13,"Pass","Fail") -> Fail
A32: ='Golden Dataset'!A29 -> R-08076 | B32: ='Golden Dataset'!I29 -> Abuse: repeated damage claims | C32: =MIN(99,$M$5*'Golden Dataset'!E29+$M$6*'Golden Dataset'!F29+IF('Golden Dataset'!G29<30,$M$7,0)+IF('Golden Dataset'!H29="No",$M$8,0)) -> 8 | D32: =IF(C32>=$M$9,"Hold and review",IF(C32>=$M$10,"Refund on carrier scan","Approve")) -> Approve | E32: =IF(C32>=$M$9,1,0) -> 0 | F32: =IF(LEFT(B32,5)="Abuse",1,0) -> 1 | G32: =IF(B32="Abuse: refund without return",1,0) -> 0 | H32: =IF(E32=1,IF(F32=1,"Correct hold","False alarm"),IF(F32=1,"Missed","Correctly left alone")) -> Missed | L32: 60 | M32: =COUNTIF($C$5:$C$204,">="&L32) -> 30 | N32: =COUNTIFS($C$5:$C$204,">="&L32,$F$5:$F$204,1) -> 29 | O32: =IFERROR(N32/M32,0) -> 0.96666667 | P32: =COUNTIFS($C$5:$C$204,">="&L32,$G$5:$G$204,1) -> 20 | Q32: =IFERROR(P32/SUM($G$5:$G$204),0) -> 0.68965517 | R32: =$M$11*$M$12*Q32 -> 14.110345 | S32: =IF(O32>=$M$13,"Pass","Fail") -> Pass
A33: ='Golden Dataset'!A30 -> R-08149 | B33: ='Golden Dataset'!I30 -> Honest | C33: =MIN(99,$M$5*'Golden Dataset'!E30+$M$6*'Golden Dataset'!F30+IF('Golden Dataset'!G30<30,$M$7,0)+IF('Golden Dataset'!H30="No",$M$8,0)) -> 0 | D33: =IF(C33>=$M$9,"Hold and review",IF(C33>=$M$10,"Refund on carrier scan","Approve")) -> Approve | E33: =IF(C33>=$M$9,1,0) -> 0 | F33: =IF(LEFT(B33,5)="Abuse",1,0) -> 0 | G33: =IF(B33="Abuse: refund without return",1,0) -> 0 | H33: =IF(E33=1,IF(F33=1,"Correct hold","False alarm"),IF(F33=1,"Missed","Correctly left alone")) -> Correctly left alone | L33: 70 | M33: =COUNTIF($C$5:$C$204,">="&L33) -> 23 | N33: =COUNTIFS($C$5:$C$204,">="&L33,$F$5:$F$204,1) -> 23 | O33: =IFERROR(N33/M33,0) -> 1 | P33: =COUNTIFS($C$5:$C$204,">="&L33,$G$5:$G$204,1) -> 17 | Q33: =IFERROR(P33/SUM($G$5:$G$204),0) -> 0.5862069 | R33: =$M$11*$M$12*Q33 -> 11.993793 | S33: =IF(O33>=$M$13,"Pass","Fail") -> Pass
A34: ='Golden Dataset'!A31 -> R-08105 | B34: ='Golden Dataset'!I31 -> Abuse: refund without return | C34: =MIN(99,$M$5*'Golden Dataset'!E31+$M$6*'Golden Dataset'!F31+IF('Golden Dataset'!G31<30,$M$7,0)+IF('Golden Dataset'!H31="No",$M$8,0)) -> 30 | D34: =IF(C34>=$M$9,"Hold and review",IF(C34>=$M$10,"Refund on carrier scan","Approve")) -> Refund on carrier scan | E34: =IF(C34>=$M$9,1,0) -> 0 | F34: =IF(LEFT(B34,5)="Abuse",1,0) -> 1 | G34: =IF(B34="Abuse: refund without return",1,0) -> 1 | H34: =IF(E34=1,IF(F34=1,"Correct hold","False alarm"),IF(F34=1,"Missed","Correctly left alone")) -> Missed | L34: 80 | M34: =COUNTIF($C$5:$C$204,">="&L34) -> 18 | N34: =COUNTIFS($C$5:$C$204,">="&L34,$F$5:$F$204,1) -> 18 | O34: =IFERROR(N34/M34,0) -> 1 | P34: =COUNTIFS($C$5:$C$204,">="&L34,$G$5:$G$204,1) -> 12 | Q34: =IFERROR(P34/SUM($G$5:$G$204),0) -> 0.4137931 | R34: =$M$11*$M$12*Q34 -> 8.4662069 | S34: =IF(O34>=$M$13,"Pass","Fail") -> Pass
A35: ='Golden Dataset'!A32 -> R-08036 | B35: ='Golden Dataset'!I32 -> Honest | C35: =MIN(99,$M$5*'Golden Dataset'!E32+$M$6*'Golden Dataset'!F32+IF('Golden Dataset'!G32<30,$M$7,0)+IF('Golden Dataset'!H32="No",$M$8,0)) -> 0 | D35: =IF(C35>=$M$9,"Hold and review",IF(C35>=$M$10,"Refund on carrier scan","Approve")) -> Approve | E35: =IF(C35>=$M$9,1,0) -> 0 | F35: =IF(LEFT(B35,5)="Abuse",1,0) -> 0 | G35: =IF(B35="Abuse: refund without return",1,0) -> 0 | H35: =IF(E35=1,IF(F35=1,"Correct hold","False alarm"),IF(F35=1,"Missed","Correctly left alone")) -> Correctly left alone | L35: 90 | M35: =COUNTIF($C$5:$C$204,">="&L35) -> 15 | N35: =COUNTIFS($C$5:$C$204,">="&L35,$F$5:$F$204,1) -> 15 | O35: =IFERROR(N35/M35,0) -> 1 | P35: =COUNTIFS($C$5:$C$204,">="&L35,$G$5:$G$204,1) -> 9 | Q35: =IFERROR(P35/SUM($G$5:$G$204),0) -> 0.31034483 | R35: =$M$11*$M$12*Q35 -> 6.3496552 | S35: =IF(O35>=$M$13,"Pass","Fail") -> Pass
A36: ='Golden Dataset'!A33 -> R-08074 | B36: ='Golden Dataset'!I33 -> Honest | C36: =MIN(99,$M$5*'Golden Dataset'!E33+$M$6*'Golden Dataset'!F33+IF('Golden Dataset'!G33<30,$M$7,0)+IF('Golden Dataset'!H33="No",$M$8,0)) -> 0 | D36: =IF(C36>=$M$9,"Hold and review",IF(C36>=$M$10,"Refund on carrier scan","Approve")) -> Approve | E36: =IF(C36>=$M$9,1,0) -> 0 | F36: =IF(LEFT(B36,5)="Abuse",1,0) -> 0 | G36: =IF(B36="Abuse: refund without return",1,0) -> 0 | H36: =IF(E36=1,IF(F36=1,"Correct hold","False alarm"),IF(F36=1,"Missed","Correctly left alone")) -> Correctly left alone
A37: ='Golden Dataset'!A34 -> R-08023 | B37: ='Golden Dataset'!I34 -> Honest | C37: =MIN(99,$M$5*'Golden Dataset'!E34+$M$6*'Golden Dataset'!F34+IF('Golden Dataset'!G34<30,$M$7,0)+IF('Golden Dataset'!H34="No",$M$8,0)) -> 0 | D37: =IF(C37>=$M$9,"Hold and review",IF(C37>=$M$10,"Refund on carrier scan","Approve")) -> Approve | E37: =IF(C37>=$M$9,1,0) -> 0 | F37: =IF(LEFT(B37,5)="Abuse",1,0) -> 0 | G37: =IF(B37="Abuse: refund without return",1,0) -> 0 | H37: =IF(E37=1,IF(F37=1,"Correct hold","False alarm"),IF(F37=1,"Missed","Correctly left alone")) -> Correctly left alone | L37: Precision here is measured on a dataset where abuse is over-sampled (34% of rows vs ~10% in real traffic), so real-world precision will be lower. Shadow mode re-measures it on live returns before launch.
A38: ='Golden Dataset'!A35 -> R-08151 | B38: ='Golden Dataset'!I35 -> Honest | C38: =MIN(99,$M$5*'Golden Dataset'!E35+$M$6*'Golden Dataset'!F35+IF('Golden Dataset'!G35<30,$M$7,0)+IF('Golden Dataset'!H35="No",$M$8,0)) -> 0 | D38: =IF(C38>=$M$9,"Hold and review",IF(C38>=$M$10,"Refund on carrier scan","Approve")) -> Approve | E38: =IF(C38>=$M$9,1,0) -> 0 | F38: =IF(LEFT(B38,5)="Abuse",1,0) -> 0 | G38: =IF(B38="Abuse: refund without return",1,0) -> 0 | H38: =IF(E38=1,IF(F38=1,"Correct hold","False alarm"),IF(F38=1,"Missed","Correctly left alone")) -> Correctly left alone | L38: Wear-and-return and damage-claim abuse score near zero by design: the MVP columns can't see them. V2 adds warehouse grading and chat-claim columns.
A39: ='Golden Dataset'!A36 -> R-08184 | B39: ='Golden Dataset'!I36 -> Honest | C39: =MIN(99,$M$5*'Golden Dataset'!E36+$M$6*'Golden Dataset'!F36+IF('Golden Dataset'!G36<30,$M$7,0)+IF('Golden Dataset'!H36="No",$M$8,0)) -> 0 | D39: =IF(C39>=$M$9,"Hold and review",IF(C39>=$M$10,"Refund on carrier scan","Approve")) -> Approve | E39: =IF(C39>=$M$9,1,0) -> 0 | F39: =IF(LEFT(B39,5)="Abuse",1,0) -> 0 | G39: =IF(B39="Abuse: refund without return",1,0) -> 0 | H39: =IF(E39=1,IF(F39=1,"Correct hold","False alarm"),IF(F39=1,"Missed","Correctly left alone")) -> Correctly left alone
A40: ='Golden Dataset'!A37 -> R-08189 | B40: ='Golden Dataset'!I37 -> Honest | C40: =MIN(99,$M$5*'Golden Dataset'!E37+$M$6*'Golden Dataset'!F37+IF('Golden Dataset'!G37<30,$M$7,0)+IF('Golden Dataset'!H37="No",$M$8,0)) -> 0 | D40: =IF(C40>=$M$9,"Hold and review",IF(C40>=$M$10,"Refund on carrier scan","Approve")) -> Approve | E40: =IF(C40>=$M$9,1,0) -> 0 | F40: =IF(LEFT(B40,5)="Abuse",1,0) -> 0 | G40: =IF(B40="Abuse: refund without return",1,0) -> 0 | H40: =IF(E40=1,IF(F40=1,"Correct hold","False alarm"),IF(F40=1,"Missed","Correctly left alone")) -> Correctly left alone
A41: ='Golden Dataset'!A38 -> R-08107 | B41: ='Golden Dataset'!I38 -> Abuse: refund without return | C41: =MIN(99,$M$5*'Golden Dataset'!E38+$M$6*'Golden Dataset'!F38+IF('Golden Dataset'!G38<30,$M$7,0)+IF('Golden Dataset'!H38="No",$M$8,0)) -> 96 | D41: =IF(C41>=$M$9,"Hold and review",IF(C41>=$M$10,"Refund on carrier scan","Approve")) -> Hold and review | E41: =IF(C41>=$M$9,1,0) -> 1 | F41: =IF(LEFT(B41,5)="Abuse",1,0) -> 1 | G41: =IF(B41="Abuse: refund without return",1,0) -> 1 | H41: =IF(E41=1,IF(F41=1,"Correct hold","False alarm"),IF(F41=1,"Missed","Correctly left alone")) -> Correct hold
...
